[2024-04-28T21:09:30.962-0300] {local_task_job_runner.py:120} INFO - ::group::Pre task execution logs
[2024-04-28T21:09:31.002-0300] {taskinstance.py:2073} INFO - Dependencies all met for dep_context=non-requeueable deps ti=<TaskInstance: atividade_pratica_dag.update_currency manual__2024-04-29T00:08:05.979845+00:00 [queued]>
[2024-04-28T21:09:31.018-0300] {taskinstance.py:2073} INFO - Dependencies all met for dep_context=requeueable deps ti=<TaskInstance: atividade_pratica_dag.update_currency manual__2024-04-29T00:08:05.979845+00:00 [queued]>
[2024-04-28T21:09:31.019-0300] {taskinstance.py:2303} INFO - Starting attempt 1 of 1
[2024-04-28T21:09:31.050-0300] {taskinstance.py:2327} INFO - Executing <Task(PostgresOperator): update_currency> on 2024-04-29 00:08:05.979845+00:00
[2024-04-28T21:09:31.061-0300] {standard_task_runner.py:63} INFO - Started process 11706 to run task
[2024-04-28T21:09:31.066-0300] {standard_task_runner.py:90} INFO - Running: ['airflow', 'tasks', 'run', 'atividade_pratica_dag', 'update_currency', 'manual__2024-04-29T00:08:05.979845+00:00', '--job-id', '35', '--raw', '--subdir', 'DAGS_FOLDER/atividade_pratica_dag.py', '--cfg-path', '/tmp/tmpqztrg52r']
[2024-04-28T21:09:31.068-0300] {standard_task_runner.py:91} INFO - Job 35: Subtask update_currency
[2024-04-28T21:09:31.141-0300] {task_command.py:426} INFO - Running <TaskInstance: atividade_pratica_dag.update_currency manual__2024-04-29T00:08:05.979845+00:00 [running]> on host ath
[2024-04-28T21:09:31.306-0300] {taskinstance.py:2644} INFO - Exporting env vars: AIRFLOW_CTX_DAG_OWNER='airflow' AIRFLOW_CTX_DAG_ID='atividade_pratica_dag' AIRFLOW_CTX_TASK_ID='update_currency' AIRFLOW_CTX_EXECUTION_DATE='2024-04-29T00:08:05.979845+00:00' AIRFLOW_CTX_TRY_NUMBER='1' AIRFLOW_CTX_DAG_RUN_ID='manual__2024-04-29T00:08:05.979845+00:00'
[2024-04-28T21:09:31.308-0300] {taskinstance.py:430} INFO - ::endgroup::
[2024-04-28T21:09:31.308-0300] {sql.py:276} INFO - Executing: UPDATE currency SET currency_amount = currency_amount * 2 WHERE player_id inNone
[2024-04-28T21:09:31.321-0300] {taskinstance.py:441} INFO - ::group::Post task execution logs
[2024-04-28T21:09:31.608-0300] {taskinstance.py:2890} ERROR - Task failed with exception
Traceback (most recent call last):
  File "/home/athlon/projects/airflow/.venv/lib/python3.11/site-packages/airflow/models/taskinstance.py", line 465, in _execute_task
    result = _execute_callable(context=context, **execute_callable_kwargs)
             ^^^^^^^^^^^^^^^^^^^^^^^^^^^^^^^^^^^^^^^^^^^^^^^^^^^^^^^^^^^^^
  File "/home/athlon/projects/airflow/.venv/lib/python3.11/site-packages/airflow/models/taskinstance.py", line 432, in _execute_callable
    return execute_callable(context=context, **execute_callable_kwargs)
           ^^^^^^^^^^^^^^^^^^^^^^^^^^^^^^^^^^^^^^^^^^^^^^^^^^^^^^^^^^^^
  File "/home/athlon/projects/airflow/.venv/lib/python3.11/site-packages/airflow/models/baseoperator.py", line 400, in wrapper
    return func(self, *args, **kwargs)
           ^^^^^^^^^^^^^^^^^^^^^^^^^^^
  File "/home/athlon/projects/airflow/.venv/lib/python3.11/site-packages/airflow/providers/common/sql/operators/sql.py", line 277, in execute
    hook = self.get_db_hook()
           ^^^^^^^^^^^^^^^^^^
  File "/home/athlon/projects/airflow/.venv/lib/python3.11/site-packages/airflow/providers/common/sql/operators/sql.py", line 188, in get_db_hook
    return self._hook
           ^^^^^^^^^^
  File "/usr/lib/python3.11/functools.py", line 1001, in __get__
    val = self.func(instance)
          ^^^^^^^^^^^^^^^^^^^
  File "/home/athlon/projects/airflow/.venv/lib/python3.11/site-packages/airflow/providers/common/sql/operators/sql.py", line 150, in _hook
    conn = BaseHook.get_connection(conn_id)
           ^^^^^^^^^^^^^^^^^^^^^^^^^^^^^^^^
  File "/home/athlon/projects/airflow/.venv/lib/python3.11/site-packages/airflow/hooks/base.py", line 83, in get_connection
    conn = Connection.get_connection_from_secrets(conn_id)
           ^^^^^^^^^^^^^^^^^^^^^^^^^^^^^^^^^^^^^^^^^^^^^^^
  File "/home/athlon/projects/airflow/.venv/lib/python3.11/site-packages/airflow/models/connection.py", line 519, in get_connection_from_secrets
    raise AirflowNotFoundException(f"The conn_id `{conn_id}` isn't defined")
airflow.exceptions.AirflowNotFoundException: The conn_id `PG_SWORDBLAST` isn't defined
[2024-04-28T21:09:31.620-0300] {taskinstance.py:1205} INFO - Marking task as FAILED. dag_id=atividade_pratica_dag, task_id=update_currency, execution_date=20240429T000805, start_date=20240429T000931, end_date=20240429T000931
[2024-04-28T21:09:31.639-0300] {standard_task_runner.py:110} ERROR - Failed to execute job 35 for task update_currency (The conn_id `PG_SWORDBLAST` isn't defined; 11706)
[2024-04-28T21:09:31.686-0300] {local_task_job_runner.py:240} INFO - Task exited with return code 1
[2024-04-28T21:09:31.713-0300] {taskinstance.py:3482} INFO - 0 downstream tasks scheduled from follow-on schedule check
[2024-04-28T21:09:31.714-0300] {local_task_job_runner.py:222} INFO - ::endgroup::
